Workbook

Sheet RAB
A3: STANDARISASI HARGA PROJECT
A4: NO | B4: ITEM DESIGN | C4: URAIAN DESIGN | D4: SATUAN | E4: HARGA | F4: FDT-BLSN-TJWI (TANJUNGWANGI) | G4: FIBERISASI FDT-JMR1-HYWK (HAYAM WURUK) | H4: FIBERISASI FDT-JMR1-PCKY (PANCAKARYA) | I4: FIBERISASI FDT-MHTR-BRWJ ( BRAWIJAYA ) | J4: RAMBIPUJI_TO_PUGER. | K4: FIBERISASI FDT-ASBG-SUAR (SUMBERANYAR) | L4: FIBERISASI FDT-ASBG-SKRJ (SUKOREJO) | M4: TOTAL
G5: FIBERISASI FDT-JMR1-HYWK (HAYAM WURUK) | H5: FIBERISASI FDT-JMR1-PCKY (PANCAKARYA) | I5: FIBERISASI FDT-MHTR-BRWJ ( BRAWIJAYA ) | J5: RAMBIPUJI_TO_PUGER. | K5: FIBERISASI FDT-ASBG-SUAR (SUMBERANYAR) | L5: FIBERISASI FDT-ASBG-SKRJ (SUKOREJO)
A6: A. Kabel, Penyambungan, dan Pekerjaan Sipil
A8: 1 | B8: AC-ADSS-SM-12C | C8: Jasa Pemasangan Aerial Cable Fiber Optik Single Mode 12 Core G.652 C Type ADSS Cable | D8: meter | E8: 4200 | F8: 900 | G8: 4694 | H8: 4861 | I8: 5360 | K8: 4300 | L8: 2237 | M8: =(F8+G8+H8+I8+J8+K8+L8)*E8 -> 93878400
A9: 2 | B9: AC-ADSS-SM-24C | C9: Jasa Pemasangan Aerial Cable Fiber Optik Single Mode 24 Core G.652 C Type ADSS Cable | D9: meter | E9: 4200 | F9: 3152 | G9: 12788 | H9: 13354 | I9: 10020 | K9: 1277 | L9: 4632 | M9: =(F9+G9+H9+I9+J9+K9+L9)*E9 -> 189936600
A10: 3 | B10: AC-ADSS-SM-48C | C10: Jasa Pemasangan Aerial Cable Fiber Optik Single Mode 48 Core G.652 C Type ADSS Cable | D10: meter | E10: 4200 | G10: 5348 | H10: 2706 | I10: 3209 | M10: =(F10+G10+H10+I10+J10+K10+L10)*E10 -> 47304600
A11: 4 | B11: AC-ADSS-SM-96C | C11: Jasa Pemasangan Aerial Cable Fiber Optik Single Mode 96 Core G.652 C Type ADSS Cable | D11: meter | E11: 4200 | I11: 2292 | J11: 17738 | M11: =(F11+G11+H11+I11+J11+K11+L11)*E11 -> 84126000
A12: 5 | B12: AC-ADSS-SM-144C | C12: Jasa Pemasangan Aerial Cable Fiber Optik Single Mode 144 Core G.652 C Type ADSS Cable | D12: meter | E12: 3800 | F12: 3532 | M12: =(F12+G12+H12+I12+J12+K12+L12)*E12 -> 13421600
A13: 6 | B13: AC-ADSS-SM-288C | C13: Jasa Pemasangan Aerial Cable Fiber Optik Single Mode 288 Core G.652 C Type ADSS Cable | D13: meter | E13: 3800 | M13: =(F13+G13+H13+I13+J13+K13+L13)*E13 -> 0
A14: 7 | B14: JC-OF-SM-12C | C14: Jasa Pemasangan Joint Closure Untuk Fiber Optik Kapasitas 12 Core | D14: pcs | E14: 30700 | M14: =(F14+G14+H14+I14+J14+K14+L14)*E14 -> 0
A15: 8 | B15: JC-OF-SM-24C | C15: Jasa Pemasangan Joint Closure Untuk Fiber Optik Kapasitas 24 Core | D15: pcs | E15: 30700 | I15: 2 | L15: 2 | M15: =(F15+G15+H15+I15+J15+K15+L15)*E15 -> 122800
A16: 9 | B16: JC-OF-SM-48C | C16: Jasa Pemasangan Joint Closure Untuk Fiber Optik Kapasitas 48 Core | D16: pcs | E16: 49000 | G16: 2 | H16: 2 | I16: 2 | K16: 1 | M16: =(F16+G16+H16+I16+J16+K16+L16)*E16 -> 343000
A17: 10 | B17: JC-OF-SM-96C | C17: Jasa Pemasangan Joint Closure Untuk Fiber Optik Kapasitas 96 Core | D17: pcs | E17: 49000 | G17: 1 | I17: 1 | J17: 6 | M17: =(F17+G17+H17+I17+J17+K17+L17)*E17 -> 392000
A18: 11 | B18: JC-OF-SM-144C | C18: Jasa Pemasangan Joint Closure Untuk Fiber Optik Kapasitas 144 Core | D18: pcs | E18: 52500 | F18: 1 | M18: =(F18+G18+H18+I18+J18+K18+L18)*E18 -> 52500
A19: 12 | B19: JC-OF-SM-288C | C19: Jasa Pemasangan Joint Closure Untuk Fiber Optik Kapasitas 288 Core | D19: pcs | E19: 57000 | M19: =(F19+G19+H19+I19+J19+K19+L19)*E19 -> 0
A20: 13 | B20: OTB-SM-6 | C20: Jasa Pemasangan OTB Single Mode kapasitas 12 core, Adapter (SC Connector), pigtail dan protection sleeve pada cassette/box | D20: pcs | E20: 31000 | M20: =(F20+G20+H20+I20+J20+K20+L20)*E20 -> 0
A21: 14 | B21: OTB-SM-8 | C21: Jasa Pemasangan OTB Single Mode kapasitas 12 core, Adapter (SC Connector), pigtail dan protection sleeve pada cassette/box | D21: pcs | E21: 31000 | M21: =(F21+G21+H21+I21+J21+K21+L21)*E21 -> 0
A22: 15 | B22: OTB-SM-12 | C22: Jasa Pemasangan OTB Single Mode kapasitas 12 core, Adapter (SC Connector), pigtail dan protection sleeve pada cassette/box | D22: pcs | E22: 45000 | M22: =(F22+G22+H22+I22+J22+K22+L22)*E22 -> 0
A23: 16 | B23: OTB-SM-24 | C23: Jasa Pemasangan OTB Single Mode kapasitas 24 core, Adapter (SC Connector), pigtail dan protection sleeve pada cassette/box | D23: pcs | E23: 61000 | M23: =(F23+G23+H23+I23+J23+K23+L23)*E23 -> 0
A24: 17 | B24: OTB-SM-48 | C24: Jasa Pemasangan OTB Single Mode kapasitas 48 core, Adapter (SC Connector), pigtail dan protection sleeve pada cassette/box | D24: pcs | E24: 61000 | M24: =(F24+G24+H24+I24+J24+K24+L24)*E24 -> 0
A25: 18 | B25: OTB-SM-96 | C25: Jasa Pemasangan OTB Single Mode kapasitas 96 core, Adapter (SC Connector), pigtail dan protection sleeve pada cassette/box | D25: pcs | E25: 93000 | M25: =(F25+G25+H25+I25+J25+K25+L25)*E25 -> 0
A26: 19 | B26: OTB-SM-144 | C26: Jasa Pemasangan OTB Single Mode kapasitas 144 core, Adapter (SC Connector), pigtail dan protection sleeve pada cassette/box | D26: pcs | E26: 100000 | M26: =(F26+G26+H26+I26+J26+K26+L26)*E26 -> 0
A27: 20 | B27: OTB-SM-288 | C27: Jasa Pemasangan OTB Single Mode kapasitas 288 core, Adapter (SC Connector), pigtail dan protection sleeve pada cassette/box | D27: pcs | E27: 180000 | M27: =(F27+G27+H27+I27+J27+K27+L27)*E27 -> 0
A28: 21 | B28: PS-1-2-FDT | C28: Jasa pemasangan Passive Splitter 1:2, type modular SC/UPC, for FDT, termasuk pigtail | D28: pcs | E28: 30575 | M28: =(F28+G28+H28+I28+J28+K28+L28)*E28 -> 0
A29: 22 | B29: PS-1-4-FDT | C29: Jasa pemasangan Passive Splitter 1:4, type modular SC/UPC, for FDT, termasuk pigtail | D29: pcs | E29: 30575 | F29: =F33/4 -> 8 | G29: 31 | H29: =H33/4 -> 20 | I29: =I33/4 -> 28 | K29: =K33/4 -> 10 | L29: 25 | M29: =(F29+G29+H29+I29+J29+K29+L29)*E29 -> 3730150
A30: 23 | B30: PS-1-8-FAT | C30: Jasa pemasangan Passive Splitter 1:8, type modular SC/UPC, for FAT, termasuk pigtail | D30: pcs | E30: 30575 | M30: =(F30+G30+H30+I30+J30+K30+L30)*E30 -> 0
A31: 24 | B31: PS-1-16-FAT | C31: Jasa pemasangan Passive Splitter 1:16, type modular SC/UPC, for FAT, termasuk pigtail | D31: pcs | E31: 30575 | F31: =F33 -> 32 | G31: =G33 -> 121 | H31: =H33 -> 80 | I31: =I33 -> 112 | K31: =K33 -> 40 | L31: =L33 -> 99 | M31: =(F31+G31+H31+I31+J31+K31+L31)*E31 -> 14798300
A32: 25 | B32: FAT-PB-8C-SOLID | C32: Jasa pemasangan FAT type POLE Kap 8 core adaptor SC/UPC terdiri dari 1 Box Spliter (termasuk 1 spliter 1:8), 1 Box beserta Accessories, berikut pelabelan. | D32: pcs | E32: 100000 | M32: =(F32+G32+H32+I32+J32+K32+L32)*E32 -> 0
A33: 26 | B33: FAT-PB-16C-SOLID | C33: Jasa pemasangan FAT type POLE Kap 16 core adaptor SC/UPC terdiri dari 2Box Spliter (termasuk 2 spliter 1:8), 1 Box beserta Accessories, berikut pelabelan. | D33: pcs | E33: 100000 | F33: 32 | G33: 121 | H33: 80 | I33: 112 | K33: 40 | L33: 99 | M33: =(F33+G33+H33+I33+J33+K33+L33)*E33 -> 48400000
A34: 27 | B34: Base Tray ODC | C34: Jasa pemasangan OTB termasuk terminasi dan penyambungan kabel optik Single mode kap 12 core serta Adapter (SC Connector), pigtail dan protection sleeve pada cassette/box | D34: pcs | E34: 80000 | M34: =(F34+G34+H34+I34+J34+K34+L34)*E34 -> 0
A35: 28 | B35: FAT-PDSTL-8 | C35: Jasa pemasangan FAT ( Pedestal ) kap 8 core termasuk pigtail, berikut space 1 splitter (1:8) dan Pelabelan | D35: pcs | E35: 150000 | M35: =(F35+G35+H35+I35+J35+K35+L35)*E35 -> 0
A36: 29 | B36: FAT-PDSTL-16 | C36: Jasa pemasangan FAT ( Pedestal ) kap 16 core termasuk pigtail, berikut space 1 splitter (1:16) dan Pelabelan | D36: pcs | E36: 150000 | M36: =(F36+G36+H36+I36+J36+K36+L36)*E36 -> 0
A37: 30 | B37: FDT-POLE-48C | C37: Jasa pemasangan FDT-Pole (Outdoor) With Space For Passive Splitter, Adaptor SC Kapasitas 48 Core, Berikut Pelabelan | D37: pcs | E37: 850000 | M37: =(F37+G37+H37+I37+J37+K37+L37)*E37 -> 0
A38: 31 | B38: FDT-POLE-96C | C38: Jasa pemasangan FDT-Pole (Outdoor) With Space For Passive Splitter, Adaptor SC Kapasitas 96 Core, Berikut Pelabelan | D38: pcs | E38: 2700000 | M38: =(F38+G38+H38+I38+J38+K38+L38)*E38 -> 0
A39: 32 | B39: FDT-STDG-96C | C39: Jasa pemasangan Kabinet FDT(Outdoor) With Space For Passive Splitter, Adaptor SC Kapasitas 96 Core, Berikut Pelabelan | D39: pcs | E39: 4700000 | M39: =(F39+G39+H39+I39+J39+K39+L39)*E39 -> 0
A40: 33 | B40: FDT-STDG-144C | C40: Jasa pemasangan Kabinet FDT(Outdoor) With Space For Passive Splitter, Adaptor SC Kapasitas 144 Core, Berikut Pelabelan | D40: pcs | E40: 5100000 | F40: 1 | K40: 1 | M40: =(F40+G40+H40+I40+J40+K40+L40)*E40 -> 10200000
A41: 34 | B41: FDT-STDG-288C | C41: Jasa pemasangan Kabinet FDT(Outdoor) With Space For Passive Splitter, Adaptor SC Kapasitas 288 Core, Berikut Pelabelan | D41: pcs | E41: 5300000 | G41: 1 | H41: 1 | I41: 1 | L41: 1 | M41: =(F41+G41+H41+I41+J41+K41+L41)*E41 -> 21200000
A42: 35 | B42: NP-6.0-100-1S | C42: Jasa pemasangan New Pole 6 Meter 2,5" x 600, Berikut Cat dengan warna identitas Kuning (atas) Biru (Bawah) & Cor Pondasi dengan Kekuatan Tarik 100 Kg | D42: pcs | E42: 175000 | M42: =(F42+G42+H42+I42+J42+K42+L42)*E42 -> 0
A43: 36 | B43: NP-7.0-140-2S | C43: Jasa pemasangan New Pole 7 Meter 600 x 3",200 x 3" x 100 x 2,5" , Berikut Cat dengan warna identitas Kuning (atas) Biru (bawah) | D43: pcs | E43: 250000 | M43: =(F43+G43+H43+I43+J43+K43+L43)*E43 -> 0
...

Sheet REKAP 
A1: NO | B1: KAB | C1: NAMA LOP | D1: NILAI SETCO | E1: NILAI MANDOR
A2: 1 | B2: BANYU WANGI | C2: FDT-BLSN-TJWI (TANJUNGWANGI) | D2: =RAB!F115 -> 244700620 | E2: =MANDOR!F92 -> 111575730
A3: 2 | B3: JEMBER | C3: FIBERISASI FDT-JMR1-HYWK (HAYAM WURUK) | D3: =RAB!G115 -> 388896660 | E3: =MANDOR!G92 -> 145245730
A4: 3 | B4: JEMBER | C4: FIBERISASI FDT-JMR1-PCKY (PANCAKARYA) | D4: =RAB!H115 -> 341522828 | E4: =MANDOR!H92 -> 127995230
A5: 4 | B5: JEMBER | C5: FIBERISASI FDT-MHTR-BRWJ ( BRAWIJAYA ) | D5: =RAB!I115 -> 349249832 | E5: =MANDOR!I92 -> 137912960
A6: 5 | B6: JEMBER | C6: RAMBIPUJI_TO_PUGER. | D6: =RAB!J115 -> 773192960 | E6: =MANDOR!J92 -> 382881580
A7: 6 | B7: SITUBONDO | C7: FIBERISASI FDT-ASBG-SUAR (SUMBERANYAR) | D7: =RAB!K115 -> 110936035 | E7: =MANDOR!K92 -> 43947584
A8: 7 | B8: SITUBONDO | C8: FIBERISASI FDT-ASBG-SKRJ (SUKOREJO) | D8: =RAB!L115 -> 167034012 | E8: =MANDOR!L92 -> 68001230
A9: TOTAL | D9: =SUM(D2:D8) -> 2375532947 | E9: =SUM(E2:E8) -> 1.01756e+09
C10: DEV | D10: =D9-E9 -> 1.3579729e+09

Sheet MANDOR
B2: ITEM DESIGN | C2: URAIAN DESIGN | D2: SATUAN | E2: HARGA MANDOR | F2: VOL TANJUNGWANGI | G2: VOL HAYAM WURUK | H2: VOL PANCAKARYA | I2: FIBERISASI FDT-MHTR-BRWJ ( BRAWIJAYA ) | J2: RAMBIPUJI_TO_PUGER. | K2: FIBERISASI FDT-ASBG-SUAR (SUMBERANYAR) | L2: FIBERISASI FDT-ASBG-SKRJ (SUKOREJO) | M2: TOTAL
I3: FIBERISASI FDT-MHTR-BRWJ ( BRAWIJAYA ) | J3: RAMBIPUJI_TO_PUGER. | K3: FIBERISASI FDT-ASBG-SUAR (SUMBERANYAR) | L3: FIBERISASI FDT-ASBG-SKRJ (SUKOREJO)
B5: AC-ADSS-SM-12C | C5: Jasa Pemasangan Aerial Cable Fiber Optik Single Mode 12 Core G.652 C Type ADSS Cable | D5: meter | E5: 2000 | F5: =VLOOKUP(B5,RAB!$B$8:$H$111,5,0) -> 900 | G5: =VLOOKUP(B5,RAB!$B$8:$H$111,6,0) -> 4694 | H5: =VLOOKUP(B5,RAB!$B$8:$H$111,7,0) -> 4861 | I5: =VLOOKUP(B5,RAB!$B$8:$L$114,8,0) -> 5360 | J5: =VLOOKUP(B5,RAB!$B$8:$L$114,9,0) -> 0 | K5: =VLOOKUP(B5,RAB!$B$8:$L$114,10,0) -> 4300 | L5: =VLOOKUP(B5,RAB!$B$8:$L$114,11,0) -> 2237 | M5: =(H5+G5+F5+I5+J5+K5+L5)*E5 -> 44704000
B6: AC-ADSS-SM-24C | C6: Jasa Pemasangan Aerial Cable Fiber Optik Single Mode 24 Core G.652 C Type ADSS Cable | D6: meter | E6: 2000 | F6: =VLOOKUP(B6,RAB!$B$8:$H$111,5,0) -> 3152 | G6: =VLOOKUP(B6,RAB!$B$8:$H$111,6,0) -> 12788 | H6: =VLOOKUP(B6,RAB!$B$8:$H$111,7,0) -> 13354 | I6: =VLOOKUP(B6,RAB!$B$8:$L$114,8,0) -> 10020 | J6: =VLOOKUP(B6,RAB!$B$8:$L$114,9,0) -> 0 | K6: =VLOOKUP(B6,RAB!$B$8:$L$114,10,0) -> 1277 | L6: =VLOOKUP(B6,RAB!$B$8:$L$114,11,0) -> 4632 | M6: =(H6+G6+F6+I6+J6+K6+L6)*E6 -> 90446000
B7: AC-ADSS-SM-48C | C7: Jasa Pemasangan Aerial Cable Fiber Optik Single Mode 48 Core G.652 C Type ADSS Cable | D7: meter | E7: 2000 | F7: =VLOOKUP(B7,RAB!$B$8:$H$111,5,0) -> 0 | G7: =VLOOKUP(B7,RAB!$B$8:$H$111,6,0) -> 5348 | H7: =VLOOKUP(B7,RAB!$B$8:$H$111,7,0) -> 2706 | I7: =VLOOKUP(B7,RAB!$B$8:$L$114,8,0) -> 3209 | J7: =VLOOKUP(B7,RAB!$B$8:$L$114,9,0) -> 0 | K7: =VLOOKUP(B7,RAB!$B$8:$L$114,10,0) -> 0 | L7: =VLOOKUP(B7,RAB!$B$8:$L$114,11,0) -> 0 | M7: =(H7+G7+F7+I7+J7+K7+L7)*E7 -> 22526000
B8: AC-ADSS-SM-96C | C8: Jasa Pemasangan Aerial Cable Fiber Optik Single Mode 96 Core G.652 C Type ADSS Cable | D8: meter | E8: 2000 | F8: =VLOOKUP(B8,RAB!$B$8:$H$111,5,0) -> 0 | G8: =VLOOKUP(B8,RAB!$B$8:$H$111,6,0) -> 0 | H8: =VLOOKUP(B8,RAB!$B$8:$H$111,7,0) -> 0 | I8: =VLOOKUP(B8,RAB!$B$8:$L$114,8,0) -> 2292 | J8: =VLOOKUP(B8,RAB!$B$8:$L$114,9,0) -> 17738 | K8: =VLOOKUP(B8,RAB!$B$8:$L$114,10,0) -> 0 | L8: =VLOOKUP(B8,RAB!$B$8:$L$114,11,0) -> 0 | M8: =(H8+G8+F8+I8+J8+K8+L8)*E8 -> 40060000
B9: AC-ADSS-SM-144C | C9: Jasa Pemasangan Aerial Cable Fiber Optik Single Mode 144 Core G.652 C Type ADSS Cable | D9: meter | E9: 1900 | F9: =VLOOKUP(B9,RAB!$B$8:$H$111,5,0) -> 3532 | G9: =VLOOKUP(B9,RAB!$B$8:$H$111,6,0) -> 0 | H9: =VLOOKUP(B9,RAB!$B$8:$H$111,7,0) -> 0 | I9: =VLOOKUP(B9,RAB!$B$8:$L$114,8,0) -> 0 | J9: =VLOOKUP(B9,RAB!$B$8:$L$114,9,0) -> 0 | K9: =VLOOKUP(B9,RAB!$B$8:$L$114,10,0) -> 0 | L9: =VLOOKUP(B9,RAB!$B$8:$L$114,11,0) -> 0 | M9: =(H9+G9+F9+I9+J9+K9+L9)*E9 -> 6710800
B10: AC-ADSS-SM-288C | C10: Jasa Pemasangan Aerial Cable Fiber Optik Single Mode 288 Core G.652 C Type ADSS Cable | D10: meter | E10: 1900 | F10: =VLOOKUP(B10,RAB!$B$8:$H$111,5,0) -> 0 | G10: =VLOOKUP(B10,RAB!$B$8:$H$111,6,0) -> 0 | H10: =VLOOKUP(B10,RAB!$B$8:$H$111,7,0) -> 0 | I10: =VLOOKUP(B10,RAB!$B$8:$L$114,8,0) -> 0 | J10: =VLOOKUP(B10,RAB!$B$8:$L$114,9,0) -> 0 | K10: =VLOOKUP(B10,RAB!$B$8:$L$114,10,0) -> 0 | L10: =VLOOKUP(B10,RAB!$B$8:$L$114,11,0) -> 0 | M10: =(H10+G10+F10+I10+J10+K10+L10)*E10 -> 0
B11: JC-OF-SM-12C | C11: Jasa Pemasangan Joint Closure Untuk Fiber Optik Kapasitas 12 Core | D11: pcs | E11: 20000 | F11: =VLOOKUP(B11,RAB!$B$8:$H$111,5,0) -> 0 | G11: =VLOOKUP(B11,RAB!$B$8:$H$111,6,0) -> 0 | H11: =VLOOKUP(B11,RAB!$B$8:$H$111,7,0) -> 0 | I11: =VLOOKUP(B11,RAB!$B$8:$L$114,8,0) -> 0 | J11: =VLOOKUP(B11,RAB!$B$8:$L$114,9,0) -> 0 | K11: =VLOOKUP(B11,RAB!$B$8:$L$114,10,0) -> 0 | L11: =VLOOKUP(B11,RAB!$B$8:$L$114,11,0) -> 0 | M11: =(H11+G11+F11+I11+J11+K11+L11)*E11 -> 0
B12: JC-OF-SM-24C | C12: Jasa Pemasangan Joint Closure Untuk Fiber Optik Kapasitas 24 Core | D12: pcs | E12: 20000 | F12: =VLOOKUP(B12,RAB!$B$8:$H$111,5,0) -> 0 | G12: =VLOOKUP(B12,RAB!$B$8:$H$111,6,0) -> 0 | H12: =VLOOKUP(B12,RAB!$B$8:$H$111,7,0) -> 0 | I12: =VLOOKUP(B12,RAB!$B$8:$L$114,8,0) -> 2 | J12: =VLOOKUP(B12,RAB!$B$8:$L$114,9,0) -> 0 | K12: =VLOOKUP(B12,RAB!$B$8:$L$114,10,0) -> 0 | L12: =VLOOKUP(B12,RAB!$B$8:$L$114,11,0) -> 2 | M12: =(H12+G12+F12+I12+J12+K12+L12)*E12 -> 80000
B13: JC-OF-SM-48C | C13: Jasa Pemasangan Joint Closure Untuk Fiber Optik Kapasitas 48 Core | D13: pcs | E13: 25000 | F13: =VLOOKUP(B13,RAB!$B$8:$H$111,5,0) -> 0 | G13: =VLOOKUP(B13,RAB!$B$8:$H$111,6,0) -> 2 | H13: =VLOOKUP(B13,RAB!$B$8:$H$111,7,0) -> 2 | I13: =VLOOKUP(B13,RAB!$B$8:$L$114,8,0) -> 2 | J13: =VLOOKUP(B13,RAB!$B$8:$L$114,9,0) -> 0 | K13: =VLOOKUP(B13,RAB!$B$8:$L$114,10,0) -> 1 | L13: =VLOOKUP(B13,RAB!$B$8:$L$114,11,0) -> 0 | M13: =(H13+G13+F13+I13+J13+K13+L13)*E13 -> 175000
B14: JC-OF-SM-96C | C14: Jasa Pemasangan Joint Closure Untuk Fiber Optik Kapasitas 96 Core | D14: pcs | E14: 25000 | F14: =VLOOKUP(B14,RAB!$B$8:$H$111,5,0) -> 0 | G14: =VLOOKUP(B14,RAB!$B$8:$H$111,6,0) -> 1 | H14: =VLOOKUP(B14,RAB!$B$8:$H$111,7,0) -> 0 | I14: =VLOOKUP(B14,RAB!$B$8:$L$114,8,0) -> 1 | J14: =VLOOKUP(B14,RAB!$B$8:$L$114,9,0) -> 6 | K14: =VLOOKUP(B14,RAB!$B$8:$L$114,10,0) -> 0 | L14: =VLOOKUP(B14,RAB!$B$8:$L$114,11,0) -> 0 | M14: =(H14+G14+F14+I14+J14+K14+L14)*E14 -> 200000
B15: JC-OF-SM-144C | C15: Jasa Pemasangan Joint Closure Untuk Fiber Optik Kapasitas 144 Core | D15: pcs | E15: 26000 | F15: =VLOOKUP(B15,RAB!$B$8:$H$111,5,0) -> 1 | G15: =VLOOKUP(B15,RAB!$B$8:$H$111,6,0) -> 0 | H15: =VLOOKUP(B15,RAB!$B$8:$H$111,7,0) -> 0 | I15: =VLOOKUP(B15,RAB!$B$8:$L$114,8,0) -> 0 | J15: =VLOOKUP(B15,RAB!$B$8:$L$114,9,0) -> 0 | K15: =VLOOKUP(B15,RAB!$B$8:$L$114,10,0) -> 0 | L15: =VLOOKUP(B15,RAB!$B$8:$L$114,11,0) -> 0 | M15: =(H15+G15+F15+I15+J15+K15+L15)*E15 -> 26000
B16: JC-OF-SM-288C | C16: Jasa Pemasangan Joint Closure Untuk Fiber Optik Kapasitas 288 Core | D16: pcs | E16: 28000 | F16: =VLOOKUP(B16,RAB!$B$8:$H$111,5,0) -> 0 | G16: =VLOOKUP(B16,RAB!$B$8:$H$111,6,0) -> 0 | H16: =VLOOKUP(B16,RAB!$B$8:$H$111,7,0) -> 0 | I16: =VLOOKUP(B16,RAB!$B$8:$L$114,8,0) -> 0 | J16: =VLOOKUP(B16,RAB!$B$8:$L$114,9,0) -> 0 | K16: =VLOOKUP(B16,RAB!$B$8:$L$114,10,0) -> 0 | L16: =VLOOKUP(B16,RAB!$B$8:$L$114,11,0) -> 0 | M16: =(H16+G16+F16+I16+J16+K16+L16)*E16 -> 0
... B67: Klem HDPE | C67: Jasa Pekerjaan & Pengadaan Material Klem HDPE di dinding beton dengan klem ketebalan 2mm lebar 2,5 cm menggunakan dynabolt termasuk rekondisi atau perbaikan kerusakan | D67: pcs | E67: 6500 | F67: =VLOOKUP(B67,RAB!$B$8:$H$111,5,0) -> 0 | G67: =VLOOKUP(B67,RAB!$B$8:$H$111,6,0) -> 0 | H67: =VLOOKUP(B67,RAB!$B$8:$H$111,7,0) -> 0 | I67: =VLOOKUP(B67,RAB!$B$8:$L$114,8,0) -> 0 | J67: =VLOOKUP(B67,RAB!$B$8:$L$114,9,0) -> 0 | K67: =VLOOKUP(B67,RAB!$B$8:$L$114,10,0) -> 0 | L67: =VLOOKUP(B67,RAB!$B$8:$L$114,11,0) -> 0 | M67: =(H67+G67+F67+I67+J67+K67+L67)*E67 -> 0
B68: MH-HH-170 | C68: Jasa Pekerjaan & Pengadaan Material Handhole Type HH1 ukuran dimensi dalam (P X L X T = 170x150x165) cor beton 1 : 2 : 3 dengan tulisan " ID-NET " | D68: pcs | E68: 4218196.5 | I68: =VLOOKUP(B68,RAB!$B$8:$L$114,8,0) -> 0 | J68: =VLOOKUP(B68,RAB!$B$8:$L$114,9,0) -> 0 | K68: =VLOOKUP(B68,RAB!$B$8:$L$114,10,0) -> 0 | L68: =VLOOKUP(B68,RAB!$B$8:$L$114,11,0) -> 0 | M68: =(H68+G68+F68+I68+J68+K68+L68)*E68 -> 0
B69: MH-PIT-120 | C69: Jasa Pekerjaan & Pengadaan Material Handhole Type HH2 ukuran dimensi dalam (P X L X T = 120x130x165) cor beton 1 : 2 : 3 dengan tulisan " ID-NET " | D69: pcs | E69: 4182730 | F69: =VLOOKUP(B69,RAB!$B$8:$H$111,5,0) -> 1 | G69: =VLOOKUP(B69,RAB!$B$8:$H$111,6,0) -> 1 | H69: =VLOOKUP(B69,RAB!$B$8:$H$111,7,0) -> 1 | I69: =VLOOKUP(B69,RAB!$B$8:$L$114,8,0) -> 2 | J69: =VLOOKUP(B69,RAB!$B$8:$L$114,9,0) -> 6 | K69: =VLOOKUP(B69,RAB!$B$8:$L$114,10,0) -> 0 | L69: =VLOOKUP(B69,RAB!$B$8:$L$114,11,0) -> 1 | M69: =(H69+G69+F69+I69+J69+K69+L69)*E69 -> 50192760
B70: HH-PIT-80 | C70: Jasa Pekerjaan & Pengadaan Material Handhole Pit ukuran dimensi dalam (P x L x T = 80cm x 80cm x 100cm) cor beton 1 : 2 : 3 dengan tulisan " ID-NET " | D70: pcs | E70: 1583084.5 | F70: =VLOOKUP(B70,RAB!$B$8:$H$111,5,0) -> 0 | G70: =VLOOKUP(B70,RAB!$B$8:$H$111,6,0) -> 0 | H70: =VLOOKUP(B70,RAB!$B$8:$H$111,7,0) -> 0 | I70: =VLOOKUP(B70,RAB!$B$8:$L$114,8,0) -> 0 | J70: =VLOOKUP(B70,RAB!$B$8:$L$114,9,0) -> 0 | K70: =VLOOKUP(B70,RAB!$B$8:$L$114,10,0) -> 1 | L70: =VLOOKUP(B70,RAB!$B$8:$L$114,11,0) -> 0 | M70: =(H70+G70+F70+I70+J70+K70+L70)*E70 -> 1583084.5
B71: HH-PIT-P-HA | C71: Jasa Pekerjaan & Pengadaan Material Pembuatan HH Pit Portable Home Access ukuran 40cm beserta aksesorisnya | D71: pcs | E71: 297415 | F71: =VLOOKUP(B71,RAB!$B$8:$H$111,5,0) -> 0 | G71: =VLOOKUP(B71,RAB!$B$8:$H$111,6,0) -> 0 | H71: =VLOOKUP(B71,RAB!$B$8:$H$111,7,0) -> 0 | I71: =VLOOKUP(B71,RAB!$B$8:$L$114,8,0) -> 0 | J71: =VLOOKUP(B71,RAB!$B$8:$L$114,9,0) -> 0 | K71: =VLOOKUP(B71,RAB!$B$8:$L$114,10,0) -> 0 | L71: =VLOOKUP(B71,RAB!$B$8:$L$114,11,0) -> 0 | M71: =(H71+G71+F71+I71+J71+K71+L71)*E71 -> 0
B72: HH-PIT-P-FAT | C72: Jasa Pekerjaan & Pengadaan Material Pembuatan dan Pemasangan HH PIT Portable FAT beserta aksesorisnya | D72: pcs | E72: 597931.5 | F72: =VLOOKUP(B72,RAB!$B$8:$H$111,5,0) -> 0 | G72: =VLOOKUP(B72,RAB!$B$8:$H$111,6,0) -> 0 | H72: =VLOOKUP(B72,RAB!$B$8:$H$111,7,0) -> 0 | I72: =VLOOKUP(B72,RAB!$B$8:$L$114,8,0) -> 0 | J72: =VLOOKUP(B72,RAB!$B$8:$L$114,9,0) -> 0 | K72: =VLOOKUP(B72,RAB!$B$8:$L$114,10,0) -> 0 | L72: =VLOOKUP(B72,RAB!$B$8:$L$114,11,0) -> 0 | M72: =(H72+G72+F72+I72+J72+K72+L72)*E72 -> 0
B73: HH-PIT-P-FDT | C73: Jasa Pekerjaan & Pengadaan Material Pembuatan dan Pemasangan HH PIT Portable FDT beserta aksesorisnya | D73: pcs | E73: 1281959 | F73: =VLOOKUP(B73,RAB!$B$8:$H$111,5,0) -> 0 | G73: =VLOOKUP(B73,RAB!$B$8:$H$111,6,0) -> 0 | H73: =VLOOKUP(B73,RAB!$B$8:$H$111,7,0) -> 0 | I73: =VLOOKUP(B73,RAB!$B$8:$L$114,8,0) -> 0 | J73: =VLOOKUP(B73,RAB!$B$8:$L$114,9,0) -> 0 | K73: =VLOOKUP(B73,RAB!$B$8:$L$114,10,0) -> 0 | L73: =VLOOKUP(B73,RAB!$B$8:$L$114,11,0) -> 0 | M73: =(H73+G73+F73+I73+J73+K73+L73)*E73 -> 0
B74: MH-HH-REKONDISI | C74: Jasa Pekerjaan & Pengadaan Material Peninggian Tutup Manhole/Handhole | D74: pcs | E74: 740950.5 | F74: =VLOOKUP(B74,RAB!$B$8:$H$111,5,0) -> 0 | G74: =VLOOKUP(B74,RAB!$B$8:$H$111,6,0) -> 0 | H74: =VLOOKUP(B74,RAB!$B$8:$H$111,7,0) -> 0 | I74: =VLOOKUP(B74,RAB!$B$8:$L$114,8,0) -> 0 | J74: =VLOOKUP(B74,RAB!$B$8:$L$114,9,0) -> 0 | K74: =VLOOKUP(B74,RAB!$B$8:$L$114,10,0) -> 0 | L74: =VLOOKUP(B74,RAB!$B$8:$L$114,11,0) -> 0 | M74: =(H74+G74+F74+I74+J74+K74+L74)*E74 -> 0
B75: DRWG-ABD-PRJCT | C75: Jasa Pembuatan As Build Drawing Dalam Ukuran A3 Meliputi Manajemen Core, Peta Lokasi & Skema Kabel Per Segment Per Order | D75: Package | E75: 1500000 | F75: =VLOOKUP(B75,RAB!$B$8:$H$111,5,0) -> 1 | G75: =VLOOKUP(B75,RAB!$B$8:$H$111,6,0) -> 1 | H75: =VLOOKUP(B75,RAB!$B$8:$H$111,7,0) -> 1 | I75: =VLOOKUP(B75,RAB!$B$8:$L$114,8,0) -> 1 | J75: =VLOOKUP(B75,RAB!$B$8:$L$114,9,0) -> 1 | K75: =VLOOKUP(B75,RAB!$B$8:$L$114,10,0) -> 1 | L75: =VLOOKUP(B75,RAB!$B$8:$L$114,11,0) -> 1 | M75: =(H75+G75+F75+I75+J75+K75+L75)*E75 -> 10500000
B76: SITAC-FDT-MH-HH | C76: Biaya perizinan yang diberikan untuk penempatan FDT termasuk MH dan HH di dalam lahan selain PU yang bersifat restribusi | D76: Package | E76: pengajuan | F76: =VLOOKUP(B76,RAB!$B$8:$H$111,5,0) -> 1 | G76: =VLOOKUP(B76,RAB!$B$8:$H$111,6,0) -> 1 | H76: =VLOOKUP(B76,RAB!$B$8:$H$111,7,0) -> 1 | I76: =VLOOKUP(B76,RAB!$B$8:$L$114,8,0) -> 1 | J76: =VLOOKUP(B76,RAB!$B$8:$L$114,9,0) -> 0 | K76: =VLOOKUP(B76,RAB!$B$8:$L$114,10,0) -> 1 | L76: =VLOOKUP(B76,RAB!$B$8:$L$114,11,0) -> 1
B77: SLACK-SUPPORT-80 | C77: Jasa Pemasangan Slack include sabuk ukuran dimensi dalam (P x L = 80cm x 80cm) | D77: pcs | E77: 15000 | F77: =VLOOKUP(B77,RAB!$B$8:$H$111,5,0) -> 5 | G77: =VLOOKUP(B77,RAB!$B$8:$H$111,6,0) -> 2 | H77: =VLOOKUP(B77,RAB!$B$8:$H$111,7,0) -> 2 | I77: =VLOOKUP(B77,RAB!$B$8:$L$114,8,0) -> 0 | J77: =VLOOKUP(B77,RAB!$B$8:$L$114,9,0) -> 0 | K77: =VLOOKUP(B77,RAB!$B$8:$L$114,10,0) -> 1 | L77: =VLOOKUP(B77,RAB!$B$8:$L$114,11,0) -> 0 | M77: =(H77+G77+F77+I77+J77+K77+L77)*E77 -> 150000
B78: SLACK-SUPPORT-120 | C78: Jasa Pemasangan Slack include sabuk ukuran dimensi dalam (P x L = 120cm x 120cm) | D78: pcs | E78: 20000 | F78: =VLOOKUP(B78,RAB!$B$8:$H$111,5,0) -> 1 | G78: =VLOOKUP(B78,RAB!$B$8:$H$111,6,0) -> 1 | H78: =VLOOKUP(B78,RAB!$B$8:$H$111,7,0) -> 1 | I78: =VLOOKUP(B78,RAB!$B$8:$L$114,8,0) -> 2 | J78: =VLOOKUP(B78,RAB!$B$8:$L$114,9,0) -> 6 | K78: =VLOOKUP(B78,RAB!$B$8:$L$114,10,0) -> 0 | L78: =VLOOKUP(B78,RAB!$B$8:$L$114,11,0) -> 1 | M78: =(H78+G78+F78+I78+J78+K78+L78)*E78 -> 240000
B79: LABELING-KFA | C79: Jasa Pemasangan & Pengadaan label kabel Fiber Optik dengan material akrilik warna (P x L = 5cm x 15cm, tebal = 5 mm) | D79: pcs | E79: 10000 | F79: =VLOOKUP(B79,RAB!$B$8:$H$111,5,0) -> 35 | G79: =VLOOKUP(B79,RAB!$B$8:$H$111,6,0) -> 127 | H79: =VLOOKUP(B79,RAB!$B$8:$H$111,7,0) -> 85 | I79: =VLOOKUP(B79,RAB!$B$8:$L$114,8,0) -> 118 | J79: =VLOOKUP(B79,RAB!$B$8:$L$114,9,0) -> 0 | K79: =VLOOKUP(B79,RAB!$B$8:$L$114,10,0) -> 45 | L79: =VLOOKUP(B79,RAB!$B$8:$L$114,11,0) -> 103 | M79: =(H79+G79+F79+I79+J79+K79+L79)*E79 -> 5130000
B80: LABELING-PC | C80: Jasa Pemasangan & Pengadaan material termasuk jasa Pelabelan Digital dan Perapian Di Dalam FDT | D80: pcs | E80: 3500 | F80: =VLOOKUP(B80,RAB!$B$8:$H$111,5,0) -> 0 | G80: =VLOOKUP(B80,RAB!$B$8:$H$111,6,0) -> 0 | H80: =VLOOKUP(B80,RAB!$B$8:$H$111,7,0) -> 0 | I80: =VLOOKUP(B80,RAB!$B$8:$L$114,8,0) -> 0 | J80: =VLOOKUP(B80,RAB!$B$8:$L$114,9,0) -> 0 | K80: =VLOOKUP(B80,RAB!$B$8:$L$114,10,0) -> 0 | L80: =VLOOKUP(B80,RAB!$B$8:$L$114,11,0) -> 0 | M80: =(H80+G80+F80+I80+J80+K80+L80)*E80 -> 0
B81: RP-GALVANIS | C81: Jasa Pemasangan Riser Pipe Untuk Pengamanan Kabel Optik Ke FDT Pole / Titik Naik Ku Diameter 2 Inch Panjang 3 Meter | D81: pcs | E81: 26000 | F81: =VLOOKUP(B81,RAB!$B$8:$H$111,5,0) -> 3 | G81: =VLOOKUP(B81,RAB!$B$8:$H$111,6,0) -> 3 | H81: =VLOOKUP(B81,RAB!$B$8:$H$111,7,0) -> 3 | I81: =VLOOKUP(B81,RAB!$B$8:$L$114,8,0) -> 3 | J81: =VLOOKUP(B81,RAB!$B$8:$L$114,9,0) -> 0 | K81: =VLOOKUP(B81,RAB!$B$8:$L$114,10,0) -> 3 | L81: =VLOOKUP(B81,RAB!$B$8:$L$114,11,0) -> 3 | M81: =(H81+G81+F81+I81+J81+K81+L81)*E81 -> 468000
B82: FDT-PROT-144 | C82: Jasa Pemasangan Kerangkeng FDT-144, menggunakan rangka besi siku 4 cm dan ram besi beton diameter 10 mm, dengan gembok 50 mm | D82: pcs | E82: 360000 | F82: =VLOOKUP(B82,RAB!$B$8:$H$111,5,0) -> 0 | G82: =VLOOKUP(B82,RAB!$B$8:$H$111,6,0) -> 0 | H82: =VLOOKUP(B82,RAB!$B$8:$H$111,7,0) -> 0 | I82: =VLOOKUP(B82,RAB!$B$8:$L$114,8,0) -> 0 | J82: =VLOOKUP(B82,RAB!$B$8:$L$114,9,0) -> 0 | K82: =VLOOKUP(B82,RAB!$B$8:$L$114,10,0) -> 0 | L82: =VLOOKUP(B82,RAB!$B$8:$L$114,11,0) -> 0 | M82: =(H82+G82+F82+I82+J82+K82+L82)*E82 -> 0
B83: FDT-PROT-288 | C83: Jasa Pemasangan Kerangkeng FDT-288, menggunakan rangka besi siku 4 cm dan ram besi beton dia. 10 mm, dengan gembok 50 mm | D83: pcs | E83: 375000 | F83: =VLOOKUP(B83,RAB!$B$8:$H$111,5,0) -> 0 | G83: =VLOOKUP(B83,RAB!$B$8:$H$111,6,0) -> 0 | H83: =VLOOKUP(B83,RAB!$B$8:$H$111,7,0) -> 0 | I83: =VLOOKUP(B83,RAB!$B$8:$L$114,8,0) -> 0 | J83: =VLOOKUP(B83,RAB!$B$8:$L$114,9,0) -> 0 | K83: =VLOOKUP(B83,RAB!$B$8:$L$114,10,0) -> 0 | L83: =VLOOKUP(B83,RAB!$B$8:$L$114,11,0) -> 0 | M83: =(H83+G83+F83+I83+J83+K83+L83)*E83 -> 0
B84: PU-LABEL-EXST | C84: Jasa Pelabelan Tiang dengan menggunakan cat besi sesuai DESIGN PACK | D84: node | E84: 2500 | F84: =VLOOKUP(B84,RAB!$B$8:$H$111,5,0) -> 0 | G84: =VLOOKUP(B84,RAB!$B$8:$H$111,6,0) -> 0 | H84: =VLOOKUP(B84,RAB!$B$8:$H$111,7,0) -> 0 | I84: =VLOOKUP(B84,RAB!$B$8:$L$114,8,0) -> 0 | J84: =VLOOKUP(B84,RAB!$B$8:$L$114,9,0) -> 0 | K84: =VLOOKUP(B84,RAB!$B$8:$L$114,10,0) -> 0 | L84: =VLOOKUP(B84,RAB!$B$8:$L$114,11,0) -> 0 | M84: =(H84+G84+F84+I84+J84+K84+L84)*E84 -> 0
B85: MV-MATERIAL-20/39 | C85: Delivery material dalam jarak 0-20 km dari WH INTERNUSA ke on site pekerjaan per segment | D85: ls | E85: 20000 | F85: =VLOOKUP(B85,RAB!$B$8:$H$111,5,0) -> 0 | G85: =VLOOKUP(B85,RAB!$B$8:$H$111,6,0) -> 0 | H85: =VLOOKUP(B85,RAB!$B$8:$H$111,7,0) -> 0 | I85: =VLOOKUP(B85,RAB!$B$8:$L$114,8,0) -> 0 | J85: =VLOOKUP(B85,RAB!$B$8:$L$114,9,0) -> 0 | K85: =VLOOKUP(B85,RAB!$B$8:$L$114,10,0) -> 0 | L85: =VLOOKUP(B85,RAB!$B$8:$L$114,11,0) -> 0 | M85: =(H85+G85+F85+I85+J85+K85+L85)*E85 -> 0
B86: MV-MATERIAL-20/40 | C86: Delivery material dalam jarak 20-40 km dari WH INTERNUSA ke on site pekerjaan per segment | D86: ls | E86: 40000 | F86: =VLOOKUP(B86,RAB!$B$8:$H$111,5,0) -> 0 | G86: =VLOOKUP(B86,RAB!$B$8:$H$111,6,0) -> 0 | H86: =VLOOKUP(B86,RAB!$B$8:$H$111,7,0) -> 0 | I86: =VLOOKUP(B86,RAB!$B$8:$L$114,8,0) -> 0 | J86: =VLOOKUP(B86,RAB!$B$8:$L$114,9,0) -> 0 | K86: =VLOOKUP(B86,RAB!$B$8:$L$114,10,0) -> 0 | L86: =VLOOKUP(B86,RAB!$B$8:$L$114,11,0) -> 0 | M86: =(H86+G86+F86+I86+J86+K86+L86)*E86 -> 0
B87: MV-MATERIAL-40/60 | C87: Delivery material dalam jarak 40-60 km dari WH INTERNUSA ke on site pekerjaan per segment | D87: ls | E87: 80000 | F87: =VLOOKUP(B87,RAB!$B$8:$H$111,5,0) -> 0 | G87: =VLOOKUP(B87,RAB!$B$8:$H$111,6,0) -> 0 | H87: =VLOOKUP(B87,RAB!$B$8:$H$111,7,0) -> 0 | I87: =VLOOKUP(B87,RAB!$B$8:$L$114,8,0) -> 0 | J87: =VLOOKUP(B87,RAB!$B$8:$L$114,9,0) -> 0 | K87: =VLOOKUP(B87,RAB!$B$8:$L$114,10,0) -> 0 | L87: =VLOOKUP(B87,RAB!$B$8:$L$114,11,0) -> 0 | M87: =(H87+G87+F87+I87+J87+K87+L87)*E87 -> 0
B88: MV-MATERIAL-60-UP | C88: Delivery material dalam jarak >60 km dari WH INTERNUSA ke on site pekerjaan per segment | D88: ls | E88: 150000 | F88: =VLOOKUP(B88,RAB!$B$8:$H$111,5,0) -> 0 | G88: =VLOOKUP(B88,RAB!$B$8:$H$111,6,0) -> 0 | H88: =VLOOKUP(B88,RAB!$B$8:$H$111,7,0) -> 0 | I88: =VLOOKUP(B88,RAB!$B$8:$L$114,8,0) -> 0 | J88: =VLOOKUP(B88,RAB!$B$8:$L$114,9,0) -> 0 | K88: =VLOOKUP(B88,RAB!$B$8:$L$114,10,0) -> 0 | L88: =VLOOKUP(B88,RAB!$B$8:$L$114,11,0) -> 0 | M88: =(H88+G88+F88+I88+J88+K88+L88)*E88 -> 0
B89: PERMIT-HOMEPASS | C89: Nilai perizinan yang diberikan berdasarkan jumlah homepass dalam cluster dengan guidelines INTERNUSA yang berlaku | D89: lot | E89: 7500 | F89: =VLOOKUP(B89,RAB!$B$8:$H$111,5,0) -> 512 | G89: =VLOOKUP(B89,RAB!$B$8:$H$111,6,0) -> 1936 | H89: =VLOOKUP(B89,RAB!$B$8:$H$111,7,0) -> 1280 | I89: =VLOOKUP(B89,RAB!$B$8:$L$114,8,0) -> 1792 | J89: =VLOOKUP(B89,RAB!$B$8:$L$114,9,0) -> 0 | K89: =VLOOKUP(B89,RAB!$B$8:$L$114,10,0) -> 640 | L89: =VLOOKUP(B89,RAB!$B$8:$L$114,11,0) -> 1584 | M89: =(H89+G89+F89+I89+J89+K89+L89)*E89 -> 58080000
B90: SURVEY-HOMEPASS | C90: Nilai kegiatan survey yang diberikan berdasarkan jumlah homepass dalam cluster dengan guidelines INTERNUSA yang berlaku | D90: lot | E90: 2500 | I90: =VLOOKUP(B90,RAB!$B$8:$L$114,8,0) -> 1792 | J90: =VLOOKUP(B90,RAB!$B$8:$L$114,9,0) -> 0 | K90: =VLOOKUP(B90,RAB!$B$8:$L$114,10,0) -> 640 | L90: =VLOOKUP(B90,RAB!$B$8:$L$114,11,0) -> 1584 | M90: =(H90+G90+F90+I90+J90+K90+L90)*E90 -> 10040000
B91: PRELIMINARY-BCKBN-PEMDA | C91: Biaya-biaya yang timbul dalam rangka untuk perijinan, konsumsi, kompensasi dan Supervisi mulai dari LSM, Private Area dan Rumija Pemda melingkupi PU NASIONAL, PU PROVINSI dan PU KABUPATEN/ KOTA dalam dasar pekerjaan segment Backbone | D91: meter | E91: 750 | I91: =VLOOKUP(B91,RAB!$B$8:$L$114,8,0) -> 0 | J91: =VLOOKUP(B91,RAB!$B$8:$L$114,9,0) -> 0 | K91: =VLOOKUP(B91,RAB!$B$8:$L$114,10,0) -> 0 | L91: =VLOOKUP(B91,RAB!$B$8:$L$114,11,0) -> 0 | M91: =(H91+G91+F91+I91+J91+K91+L91)*E91 -> 0
B92: TOTAL | F92: =SUMPRODUCT($E$5:$E$91,F5:F91) -> 111575730 | G92: =SUMPRODUCT($E$5:$E$91,G5:G91) -> 145245730 | H92: =SUMPRODUCT($E$5:$E$91,H5:H91) -> 127995230 | I92: =SUMPRODUCT($E$5:$E$91,I5:I91) -> 137912960 | J92: =SUMPRODUCT($E$5:$E$91,J5:J91) -> 382881580 | K92: =SUMPRODUCT($E$5:$E$91,K5:K91) -> 43947584 | L92: =SUMPRODUCT($E$5:$E$91,L5:L91) -> 68001230 | M92: =SUM(M5:M91) -> 1.01756e+09
